Workbook

Sheet 00_INSTRUCTIONS
A1: Template de saisie v2 - Oficina del Peregrino 2019-2024
A3: Stratégie validée le 2026-04-17
A4: Objectif analytique | B4: Reconstituer les données nécessaires au calcul empirique du biais SJPP (ventilation Aragonés vs Francés) et à l'analyse fine des flux pèlerins sur 2019-2024.
A5: Structure 3 tables | B5: A = Temps × Camino (marginales temporelles) | B = Nationalité × Camino (marginales démographiques) | C = 4D sur 5 caminos clés (croisements denses sur voies stratégiques)
A6: Volume total | B6: ~6700 cellules réparties en 3 tables. Saisie estimée 2-3 soirées de 1h30-2h.
A8: STRUCTURE DU CLASSEUR
A9: 00_INSTRUCTIONS | B9: Ce document : marche à suivre et conventions
A10: A_temps_x_camino | B10: Table A : 6 ans × 12 mois × 8 caminos → 576 cellules
A11: B_nat_x_camino | B11: Table B : 6 ans × 15 nationalités × 8 caminos → 720 cellules
A12: C_4D_aragones | B12: Table C partie 1 : Aragonés 4D complet (1080 cellules) ⭐ PRIORITÉ ABSOLUE
A13: C_4D_frances | B13: Table C partie 2 : Francés 4D complet (1080 cellules)
A14: C_4D_portugues | B14: Table C partie 3 : Portugués 4D complet (1080 cellules)
A15: C_4D_plata | B15: Table C partie 4 : Plata 4D complet (1080 cellules)
A16: C_4D_norte | B16: Table C partie 5 : Norte 4D complet (1080 cellules)
A17: 99_controle_qualite | B17: Calculs automatiques : totaux, comparaisons AFCC, ratios biais SJPP
A19: CONVENTIONS DE SAISIE
A20: Cellules JAUNES | B20: À remplir. Nombres entiers sans séparateur (ex: 438307, PAS 438 307).
A21: Cellules GRISES | B21: Calculs auto, ne pas toucher.
A22: Cellules ORANGE | B22: Lignes/colonnes critiques pour le projet (Aragonés, Francia).
A23: Valeur manquante | B23: Laisse vide (pas 0). Mieux vaut ne pas saisir que saisir incorrect.
A24: Estimation | B24: Préfixe ~ si tu estimes (ex: ~150).
A26: ORDRE DE SAISIE RECOMMANDÉ
A27: Étape 1 (15 min) | B27: Vérifications préalables dashboard : Aragonés existe-t-il ? Croisements 4D fonctionnent-ils ? Si non, replie sur 'Lugar de comienzo' = Somport/Jaca/Canfranc.
A28: Étape 2 (Soirée 1) | B28: Saisie Table A complète + contrôles totaux annuels
A29: Étape 3 (Soirée 1 fin) | B29: Table C partie 'Aragonés' en priorité (c'est l'info critique du projet)
A30: Étape 4 (Soirée 2) | B30: Table C 'Francés' + 'Portugués'
A31: Étape 5 (Soirée 3) | B31: Table B complète + Table C 'Plata' + 'Norte'
A32: Pause-test intermédiaire | B32: Après chaque année complète en table C, vérifie l'onglet 99_controle_qualite : si les ratios semblent aberrants, arrête-toi et revérifie la source.
A34: CE QUE CE TEMPLATE PERMET D'ANALYSER
A35: Biais SJPP empirique | B35: Ratio Aragonés / (Aragonés + Francés) par année → remplace l'estimation grossière de 12%
A36: Part française sur Aragonés | B36: Combien de pèlerins 'francophones' (France + Belgique partielle) empruntent l'axe Voie d'Arles
A37: Saisonnalité Aragonés | B37: Le col du Somport est à 1632m → saisonnalité probable forte (couloir d'entrée hiver fermé)
A38: Comparaison avec AFCC | B38: Vérifier que les évolutions Oficina sont cohérentes avec les données AFCC côté France

Sheet A_temps_x_camino
A1: Table A : Temps × Camino (576 cellules)
A2: Saisie : pour chaque année, remplir mensuel × camino. Les cellules jaunes sont à compléter.
A4: Année 2019
A5: Camino \ Mois | B5: Enero | C5: Febrero | D5: Marzo | E5: Abril | F5: Mayo | G5: Junio | H5: Julio | I5: Agosto | J5: Septiembre | K5: Octubre | L5: Noviembre | M5: Diciembre | N5: Total
A6: Camino Francés | B6: 890 | C6: 1235 | D6: 3724 | E6: 17119 | F6: 25706 | G6: 28028 | H6: 27805 | I6: 33089 | J6: 25010 | K6: 20796 | L6: 4969 | M6: 1557 | N6: =SUM(B6:M6) -> 189928
A7: Camino Portugués | B7: 402 | C7: 478 | D7: 2127 | E7: 7939 | F7: 10455 | G7: 9116 | H7: 10342 | I7: 12795 | J7: 9312 | K7: 7408 | L7: 1516 | M7: 465 | N7: =SUM(B7:M7) -> 72355
A8: Camino del Norte | B8: 71 | C8: 54 | D8: 165 | E8: 914 | F8: 1992 | G8: 2768 | H8: 4328 | I8: 4109 | J8: 2335 | K8: 1747 | L8: 398 | M8: 140 | N8: =SUM(B8:M8) -> 19021
A9: Camino Primitivo | B9: 54 | C9: 90 | D9: 225 | E9: 1244 | F9: 1911 | G9: 2200 | H9: 2569 | I9: 3563 | J9: 2112 | K9: 1339 | L9: 323 | M9: 85 | N9: =SUM(B9:M9) -> 15715
A10: Camino Inglés | B10: 86 | C10: 101 | D10: 382 | E10: 1435 | F10: 1742 | G10: 1929 | H10: 2756 | I10: 3660 | J10: 1991 | K10: 1242 | L10: 319 | M10: 138 | N10: =SUM(B10:M10) -> 15781
A11: Camino Portugués de la Costa | B11: 44 | C11: 81 | D11: 456 | E11: 1884 | F11: 2952 | G11: 3157 | H11: 3025 | I11: 3877 | J11: 3902 | K11: 2390 | L11: 371 | M11: 152 | N11: =SUM(B11:M11) -> 22291
A12: Vía de la Plata | B12: 53 | C12: 59 | D12: 330 | E12: 980 | F12: 1430 | G12: 1455 | H12: 1672 | I12: 1201 | J12: 761 | K12: 884 | L12: 264 | M12: 109 | N12: =SUM(B12:M12) -> 9198
A13: Camino Aragonés | N13: =SUM(B13:M13) -> 0
A14: TOTAL mois | B14: =SUM(B6:B13) -> 1600 | C14: =SUM(C6:C13) -> 2098 | D14: =SUM(D6:D13) -> 7409 | E14: =SUM(E6:E13) -> 31515 | F14: =SUM(F6:F13) -> 46188 | G14: =SUM(G6:G13) -> 48653 | H14: =SUM(H6:H13) -> 52497 | I14: =SUM(I6:I13) -> 62294 | ... M14: =SUM(M6:M13) -> 2646 | N14: =SUM(B14:M14) -> 344289
A15: Réf AFCC 2019 | N15: 347578
A16: Écart saisie vs AFCC | N16: =N14-N15 -> -3289
A18: Année 2020
A19: Camino \ Mois | B19: Enero | C19: Febrero | D19: Marzo | E19: Abril | F19: Mayo | G19: Junio | H19: Julio | I19: Agosto | J19: Septiembre | K19: Octubre | L19: Noviembre | M19: Diciembre | N19: Total
A20: Camino Francés | B20: 923 | C20: 1212 | D20: 565 | E20: 0 | F20: 0 | G20: 1 | H20: 2393 | I20: 5250 | J20: 3021 | K20: 2198 | L20: 393 | M20: 23 | N20: =SUM(B20:M20) -> 15979
A21: Camino Portugués | B21: 419 | C21: 746 | D21: 468 | E21: 0 | F21: 0 | G21: 0 | H21: 1639 | I21: 3415 | J21: 2093 | K21: 1381 | L21: 53 | M21: 38 | N21: =SUM(B21:M21) -> 10252
A22: Camino del Norte | B22: 101 | C22: 60 | D22: 51 | E22: 0 | F22: 0 | G22: 1 | H22: 600 | I22: 1803 | J22: 743 | K22: 393 | L22: 51 | M22: 1 | N22: =SUM(B22:M22) -> 3804
A23: Camino Primitivo | B23: 45 | C23: 96 | D23: 80 | E23: 0 | F23: 0 | G23: 1 | H23: 658 | I23: 1422 | J23: 691 | K23: 391 | L23: 14 | M23: 1 | N23: =SUM(B23:M23) -> 3399
A24: Camino Inglés | B24: 137 | C24: 179 | D24: 108 | E24: 0 | F24: 0 | G24: 4 | H24: 708 | I24: 972 | J24: 547 | K24: 268 | L24: 8 | M24: 1 | N24: =SUM(B24:M24) -> 2932
A25: Camino Portugués de la Costa | B25: 110 | C25: 177 | D25: 97 | E25: 0 | F25: 0 | G25: 1 | H25: 490 | I25: 1040 | J25: 505 | K25: 307 | L25: 8 | M25: 1 | N25: =SUM(B25:M25) -> 2736
A26: Vía de la Plata | B26: 51 | C26: 83 | D26: 65 | E26: 0 | F26: 0 | G26: 0 | H26: 220 | I26: 310 | J26: 206 | K26: 140 | L26: 30 | M26: 20 | N26: =SUM(B26:M26) -> 1125
A27: Camino Aragonés | N27: =SUM(B27:M27) -> 0
A28: TOTAL mois | B28: =SUM(B20:B27) -> 1786 | C28: =SUM(C20:C27) -> 2553 | D28: =SUM(D20:D27) -> 1434 | E28: =SUM(E20:E27) -> 0 | F28: =SUM(F20:F27) -> 0 | G28: =SUM(G20:G27) -> 8 | H28: =SUM(H20:H27) -> 6708 | I28: =SUM(I20:I27) -> 14212 | ... M28: =SUM(M20:M27) -> 85 | N28: =SUM(B28:M28) -> 40227
A29: Réf AFCC 2020 | N29: 54144
A30: Écart saisie vs AFCC | N30: =N28-N29 -> -13917
A32: Année 2021
A33: Camino \ Mois | B33: Enero | C33: Febrero | D33: Marzo | E33: Abril | F33: Mayo | G33: Junio | H33: Julio | I33: Agosto | J33: Septiembre | K33: Octubre | L33: Noviembre | M33: Diciembre | N33: Total
A34: Camino Francés | B34: 20 | C34: 6 | D34: 63 | E34: 269 | F34: 1138 | G34: 3890 | H34: 8842 | I34: 10229 | J34: 11018 | K34: 10617 | L34: 3183 | M34: 1020 | N34: =SUM(B34:M34) -> 50295
A35: Camino Portugués | B35: 15 | C35: 3 | D35: 16 | E35: 193 | F35: 817 | G35: 3129 | H35: 5863 | I35: 7736 | J35: 7368 | K35: 6669 | L35: 1801 | M35: 638 | N35: =SUM(B35:M35) -> 34248
A36: Camino del Norte | B36: 3 | C36: 0 | D36: 0 | E36: 28 | F36: 168 | G36: 721 | H36: 2147 | I36: 2613 | J36: 1946 | K36: 1424 | L36: 391 | M36: 153 | N36: =SUM(B36:M36) -> 9594
A37: Camino Primitivo | B37: 5 | C37: 2 | D37: 10 | E37: 62 | F37: 273 | G37: 758 | H37: 2111 | I37: 2661 | J37: 2097 | K37: 1635 | L37: 422 | M37: 109 | N37: =SUM(B37:M37) -> 10145
A38: Camino Inglés | B38: 2 | C38: 0 | D38: 29 | E38: 78 | F38: 346 | G38: 730 | H38: 2155 | I38: 3052 | J38: 2089 | K38: 1620 | L38: 685 | M38: 191 | N38: =SUM(B38:M38) -> 10977
A39: Camino Portugués de la Costa | B39: 2 | C39: 0 | D39: 8 | E39: 42 | F39: 188 | G39: 555 | H39: 1457 | I39: 1830 | J39: 1681 | K39: 1521 | L39: 480 | M39: 178 | N39: =SUM(B39:M39) -> 7942
A40: Vía de la Plata | B40: 3 | C40: 0 | D40: 5 | E40: 66 | F40: 165 | G40: 467 | H40: 648 | I40: 713 | J40: 591 | K40: 898 | L40: 304 | M40: 185 | N40: =SUM(B40:M40) -> 4045
A41: Camino Aragonés | N41: =SUM(B41:M41) -> 0
A42: TOTAL mois | B42: =SUM(B34:B41) -> 50 | C42: =SUM(C34:C41) -> 11 | D42: =SUM(D34:D41) -> 131 | E42: =SUM(E34:E41) -> 738 | F42: =SUM(F34:F41) -> 3095 | G42: =SUM(G34:G41) -> 10250 | H42: =SUM(H34:H41) -> 23223 | I42: =SUM(I34:I41) -> 28834 | ... M42: =SUM(M34:M41) -> 2474 | N42: =SUM(B42:M42) -> 127246
A43: Réf AFCC 2021 | N43: 178912
...

Sheet B_nat_x_camino
A1: Table B : Nationalité × Camino (720 cellules)
A2: Saisie : pour chaque année, remplir nationalité × camino.
A4: Année 2019
A5: Nationalité \ Camino | B5: Camino Francés | C5: Camino Portugués | D5: Camino del Norte | E5: Camino Primitivo | F5: Camino Inglés | G5: Camino Portugués de la Costa | H5: Vía de la Plata | I5: Camino Aragonés | J5: Total
A6: España | B6: 87592 | C6: 22522 | D6: 8512 | E6: 7830 | F6: 7905 | G6: 4554 | H6: 5334 | J6: =SUM(B6:I6) -> 144249
A7: Italia | B7: 15278 | C7: 5103 | D7: 1283 | E7: 1566 | F7: 2751 | G7: 2027 | H7: 543 | J7: =SUM(B7:I7) -> 28551
A8: Alemania | B8: 8961 | C8: 9151 | D8: 2252 | E8: 976 | F8: 933 | G8: 3408 | H8: 396 | J8: =SUM(B8:I8) -> 26077
A9: Estados Unidos | B9: 13433 | C9: 3407 | D9: 901 | E9: 685 | F9: 516 | G9: 1425 | H9: 240 | J9: =SUM(B9:I9) -> 20607
A10: Portugal | B10: 1697 | C10: 10962 | D10: 209 | E10: 536 | F10: 784 | G10: 2244 | H10: 659 | J10: =SUM(B10:I10) -> 17091
A11: Francia | B11: 6611 | C11: 845 | D11: 921 | E11: 223 | F11: 82 | G11: 214 | H11: 304 | J11: =SUM(B11:I11) -> 9200
A12: Reino Unido | B12: 5534 | C12: 1397 | D12: 387 | E12: 328 | F12: 602 | G12: 582 | H12: 232 | J12: =SUM(B12:I12) -> 9062
A13: Irlanda | B13: 4461 | C13: 899 | D13: 128 | E13: 108 | F13: 283 | G13: 819 | H13: 96 | J13: =SUM(B13:I13) -> 6794
A14: Corea | B14: 7056 | C14: 548 | D14: 216 | E14: 52 | F14: 19 | G14: 265 | H14: 52 | J14: =SUM(B14:I14) -> 8208
A15: Brasil | B15: 3017 | C15: 2168 | D15: 127 | E15: 161 | F15: 81 | G15: 388 | H15: 71 | J15: =SUM(B15:I15) -> 6013
A16: Australia | B16: 3246 | C16: 978 | D16: 260 | E16: 108 | F16: 77 | G16: 537 | H16: 80 | J16: =SUM(B16:I16) -> 5286
A17: Canadá | B17: 2926 | C17: 978 | D17: 242 | E17: 127 | F17: 83 | G17: 526 | H17: 61 | J17: =SUM(B17:I17) -> 4943
... A20: México | B20: 3135 | C20: 360 | D20: 180 | E20: 211 | F20: 41 | G20: 140 | H20: 18 | J20: =SUM(B20:I20) -> 4085
A21: TOTAL nationalités | B21: =SUM(B6:B20) -> 165888 | C21: =SUM(C6:C20) -> 62480 | D21: =SUM(D6:D20) -> 16275 | E21: =SUM(E6:E20) -> 13478 | F21: =SUM(F6:F20) -> 14435 | G21: =SUM(G6:G20) -> 18238 | H21: =SUM(H6:H20) -> 8394 | I21: =SUM(I6:I20) -> 0
A24: Année 2020
A25: Nationalité \ Camino | B25: Camino Francés | C25: Camino Portugués | D25: Camino del Norte | E25: Camino Primitivo | F25: Camino Inglés | G25: Camino Portugués de la Costa | H25: Vía de la Plata | I25: Camino Aragonés | J25: Total
A26: España | J26: =SUM(B26:I26) -> 0
A27: Italia | J27: =SUM(B27:I27) -> 0
A28: Alemania | J28: =SUM(B28:I28) -> 0
A29: Estados Unidos | J29: =SUM(B29:I29) -> 0
A30: Portugal | J30: =SUM(B30:I30) -> 0
A31: Francia | J31: =SUM(B31:I31) -> 0
A32: Reino Unido | J32: =SUM(B32:I32) -> 0
A33: Irlanda | J33: =SUM(B33:I33) -> 0
A34: Corea | J34: =SUM(B34:I34) -> 0
A35: Brasil | J35: =SUM(B35:I35) -> 0
A36: Australia | J36: =SUM(B36:I36) -> 0
A37: Canadá | J37: =SUM(B37:I37) -> 0
... A40: México | J40: =SUM(B40:I40) -> 0
A41: TOTAL nationalités | B41: =SUM(B26:B40) -> 0 | C41: =SUM(C26:C40) -> 0 | D41: =SUM(D26:D40) -> 0 | E41: =SUM(E26:E40) -> 0 | F41: =SUM(F26:F40) -> 0 | G41: =SUM(G26:G40) -> 0 | H41: =SUM(H26:H40) -> 0 | I41: =SUM(I26:I40) -> 0
A44: Année 2021
A45: Nationalité \ Camino | B45: Camino Francés | C45: Camino Portugués | D45: Camino del Norte | E45: Camino Primitivo | F45: Camino Inglés | G45: Camino Portugués de la Costa | H45: Vía de la Plata | I45: Camino Aragonés | J45: Total
A46: España | J46: =SUM(B46:I46) -> 0
A47: Italia | J47: =SUM(B47:I47) -> 0
A48: Alemania | J48: =SUM(B48:I48) -> 0
A49: Estados Unidos | J49: =SUM(B49:I49) -> 0
...

Sheet C_4D_aragones
A1: Table C - 4D : Camino Aragonés ⭐ CRITIQUE PROJET
A2: 1080 cellules : 6 ans × 12 mois × 15 nationalités. Matrice mois × nationalité par année.
A4: Année 2019 - Camino Aragonés
A5: Mois \ Nationalité | B5: España | C5: Italia | D5: Alemania | E5: Estados Unidos | F5: Portugal | G5: Francia | H5: Reino Unido | I5: Irlanda | J5: Corea | K5: Brasil | L5: Australia | M5: Canadá | N5: Polonia | O5: Holanda | P5: México | Q5: Total
A6: Enero | Q6: =SUM(B6:P6) -> 0
A7: Febrero | Q7: =SUM(B7:P7) -> 0
A8: Marzo | Q8: =SUM(B8:P8) -> 0
A9: Abril | Q9: =SUM(B9:P9) -> 0
A10: Mayo | Q10: =SUM(B10:P10) -> 0
A11: Junio | Q11: =SUM(B11:P11) -> 0
A12: Julio | Q12: =SUM(B12:P12) -> 0
A13: Agosto | Q13: =SUM(B13:P13) -> 0
A14: Septiembre | Q14: =SUM(B14:P14) -> 0
A15: Octubre | Q15: =SUM(B15:P15) -> 0
A16: Noviembre | Q16: =SUM(B16:P16) -> 0
A17: Diciembre | Q17: =SUM(B17:P17) -> 0
A18: TOTAL année | B18: =SUM(B6:B17) -> 0 | C18: =SUM(C6:C17) -> 0 | D18: =SUM(D6:D17) -> 0 | E18: =SUM(E6:E17) -> 0 | F18: =SUM(F6:F17) -> 0 | G18: =SUM(G6:G17) -> 0 | H18: =SUM(H6:H17) -> 0 | I18: =SUM(I6:I17) -> 0 | ... Q18: =SUM(Q6:Q17) -> 0
A21: Année 2020 - Camino Aragonés
A22: Mois \ Nationalité | B22: España | C22: Italia | D22: Alemania | E22: Estados Unidos | F22: Portugal | G22: Francia | H22: Reino Unido | I22: Irlanda | J22: Corea | K22: Brasil | L22: Australia | M22: Canadá | N22: Polonia | O22: Holanda | P22: México | Q22: Total
A23: Enero | Q23: =SUM(B23:P23) -> 0
A24: Febrero | Q24: =SUM(B24:P24) -> 0
A25: Marzo | Q25: =SUM(B25:P25) -> 0
A26: Abril | Q26: =SUM(B26:P26) -> 0
A27: Mayo | Q27: =SUM(B27:P27) -> 0
A28: Junio | Q28: =SUM(B28:P28) -> 0
A29: Julio | Q29: =SUM(B29:P29) -> 0
A30: Agosto | Q30: =SUM(B30:P30) -> 0
A31: Septiembre | Q31: =SUM(B31:P31) -> 0
A32: Octubre | Q32: =SUM(B32:P32) -> 0
A33: Noviembre | Q33: =SUM(B33:P33) -> 0
A34: Diciembre | Q34: =SUM(B34:P34) -> 0
A35: TOTAL année | B35: =SUM(B23:B34) -> 0 | C35: =SUM(C23:C34) -> 0 | D35: =SUM(D23:D34) -> 0 | E35: =SUM(E23:E34) -> 0 | F35: =SUM(F23:F34) -> 0 | G35: =SUM(G23:G34) -> 0 | H35: =SUM(H23:H34) -> 0 | I35: =SUM(I23:I34) -> 0 | ... Q35: =SUM(Q23:Q34) -> 0
A38: Année 2021 - Camino Aragonés
A39: Mois \ Nationalité | B39: España | C39: Italia | D39: Alemania | E39: Estados Unidos | F39: Portugal | G39: Francia | H39: Reino Unido | I39: Irlanda | J39: Corea | K39: Brasil | L39: Australia | M39: Canadá | N39: Polonia | O39: Holanda | P39: México | Q39: Total
A40: Enero | Q40: =SUM(B40:P40) -> 0
A41: Febrero | Q41: =SUM(B41:P41) -> 0
A42: Marzo | Q42: =SUM(B42:P42) -> 0
A43: Abril | Q43: =SUM(B43:P43) -> 0
A44: Mayo | Q44: =SUM(B44:P44) -> 0
A45: Junio | Q45: =SUM(B45:P45) -> 0
...

Sheet C_4D_frances
A1: Table C - 4D : Camino Francés
A2: 1080 cellules : 6 ans × 12 mois × 15 nationalités. Matrice mois × nationalité par année.
A4: Année 2019 - Camino Francés
A5: Mois \ Nationalité | B5: España | C5: Italia | D5: Alemania | E5: Estados Unidos | F5: Portugal | G5: Francia | H5: Reino Unido | I5: Irlanda | J5: Corea | K5: Brasil | L5: Australia | M5: Canadá | N5: Polonia | O5: Holanda | P5: México | Q5: Total
A6: Enero | Q6: =SUM(B6:P6) -> 0
A7: Febrero | Q7: =SUM(B7:P7) -> 0
A8: Marzo | Q8: =SUM(B8:P8) -> 0
A9: Abril | Q9: =SUM(B9:P9) -> 0
A10: Mayo | Q10: =SUM(B10:P10) -> 0
A11: Junio | Q11: =SUM(B11:P11) -> 0
A12: Julio | Q12: =SUM(B12:P12) -> 0
A13: Agosto | Q13: =SUM(B13:P13) -> 0
A14: Septiembre | Q14: =SUM(B14:P14) -> 0
A15: Octubre | Q15: =SUM(B15:P15) -> 0
A16: Noviembre | Q16: =SUM(B16:P16) -> 0
A17: Diciembre | Q17: =SUM(B17:P17) -> 0
A18: TOTAL année | B18: =SUM(B6:B17) -> 0 | C18: =SUM(C6:C17) -> 0 | D18: =SUM(D6:D17) -> 0 | E18: =SUM(E6:E17) -> 0 | F18: =SUM(F6:F17) -> 0 | G18: =SUM(G6:G17) -> 0 | H18: =SUM(H6:H17) -> 0 | I18: =SUM(I6:I17) -> 0 | ... Q18: =SUM(Q6:Q17) -> 0
A21: Année 2020 - Camino Francés
A22: Mois \ Nationalité | B22: España | C22: Italia | D22: Alemania | E22: Estados Unidos | F22: Portugal | G22: Francia | H22: Reino Unido | I22: Irlanda | J22: Corea | K22: Brasil | L22: Australia | M22: Canadá | N22: Polonia | O22: Holanda | P22: México | Q22: Total
A23: Enero | Q23: =SUM(B23:P23) -> 0
A24: Febrero | Q24: =SUM(B24:P24) -> 0
A25: Marzo | Q25: =SUM(B25:P25) -> 0
A26: Abril | Q26: =SUM(B26:P26) -> 0
A27: Mayo | Q27: =SUM(B27:P27) -> 0
A28: Junio | Q28: =SUM(B28:P28) -> 0
A29: Julio | Q29: =SUM(B29:P29) -> 0
A30: Agosto | Q30: =SUM(B30:P30) -> 0
A31: Septiembre | Q31: =SUM(B31:P31) -> 0
A32: Octubre | Q32: =SUM(B32:P32) -> 0
A33: Noviembre | Q33: =SUM(B33:P33) -> 0
A34: Diciembre | Q34: =SUM(B34:P34) -> 0
A35: TOTAL année | B35: =SUM(B23:B34) -> 0 | C35: =SUM(C23:C34) -> 0 | D35: =SUM(D23:D34) -> 0 | E35: =SUM(E23:E34) -> 0 | F35: =SUM(F23:F34) -> 0 | G35: =SUM(G23:G34) -> 0 | H35: =SUM(H23:H34) -> 0 | I35: =SUM(I23:I34) -> 0 | ... Q35: =SUM(Q23:Q34) -> 0
A38: Année 2021 - Camino Francés
A39: Mois \ Nationalité | B39: España | C39: Italia | D39: Alemania | E39: Estados Unidos | F39: Portugal | G39: Francia | H39: Reino Unido | I39: Irlanda | J39: Corea | K39: Brasil | L39: Australia | M39: Canadá | N39: Polonia | O39: Holanda | P39: México | Q39: Total
A40: Enero | Q40: =SUM(B40:P40) -> 0
A41: Febrero | Q41: =SUM(B41:P41) -> 0
A42: Marzo | Q42: =SUM(B42:P42) -> 0
A43: Abril | Q43: =SUM(B43:P43) -> 0
A44: Mayo | Q44: =SUM(B44:P44) -> 0
A45: Junio | Q45: =SUM(B45:P45) -> 0
...

Sheet C_4D_portugues
A1: Table C - 4D : Camino Portugués
A2: 1080 cellules : 6 ans × 12 mois × 15 nationalités. Matrice mois × nationalité par année.
A4: Année 2019 - Camino Portugués
A5: Mois \ Nationalité | B5: España | C5: Italia | D5: Alemania | E5: Estados Unidos | F5: Portugal | G5: Francia | H5: Reino Unido | I5: Irlanda | J5: Corea | K5: Brasil | L5: Australia | M5: Canadá | N5: Polonia | O5: Holanda | P5: México | Q5: Total
A6: Enero | Q6: =SUM(B6:P6) -> 0
A7: Febrero | Q7: =SUM(B7:P7) -> 0
A8: Marzo | Q8: =SUM(B8:P8) -> 0
A9: Abril | Q9: =SUM(B9:P9) -> 0
A10: Mayo | Q10: =SUM(B10:P10) -> 0
A11: Junio | Q11: =SUM(B11:P11) -> 0
A12: Julio | Q12: =SUM(B12:P12) -> 0
A13: Agosto | Q13: =SUM(B13:P13) -> 0
A14: Septiembre | Q14: =SUM(B14:P14) -> 0
A15: Octubre | Q15: =SUM(B15:P15) -> 0
A16: Noviembre | Q16: =SUM(B16:P16) -> 0
A17: Diciembre | Q17: =SUM(B17:P17) -> 0
A18: TOTAL année | B18: =SUM(B6:B17) -> 0 | C18: =SUM(C6:C17) -> 0 | D18: =SUM(D6:D17) -> 0 | E18: =SUM(E6:E17) -> 0 | F18: =SUM(F6:F17) -> 0 | G18: =SUM(G6:G17) -> 0 | H18: =SUM(H6:H17) -> 0 | I18: =SUM(I6:I17) -> 0 | ... Q18: =SUM(Q6:Q17) -> 0
A21: Année 2020 - Camino Portugués
A22: Mois \ Nationalité | B22: España | C22: Italia | D22: Alemania | E22: Estados Unidos | F22: Portugal | G22: Francia | H22: Reino Unido | I22: Irlanda | J22: Corea | K22: Brasil | L22: Australia | M22: Canadá | N22: Polonia | O22: Holanda | P22: México | Q22: Total
A23: Enero | Q23: =SUM(B23:P23) -> 0
A24: Febrero | Q24: =SUM(B24:P24) -> 0
A25: Marzo | Q25: =SUM(B25:P25) -> 0
A26: Abril | Q26: =SUM(B26:P26) -> 0
A27: Mayo | Q27: =SUM(B27:P27) -> 0
A28: Junio | Q28: =SUM(B28:P28) -> 0
A29: Julio | Q29: =SUM(B29:P29) -> 0
A30: Agosto | Q30: =SUM(B30:P30) -> 0
A31: Septiembre | Q31: =SUM(B31:P31) -> 0
A32: Octubre | Q32: =SUM(B32:P32) -> 0
A33: Noviembre | Q33: =SUM(B33:P33) -> 0
A34: Diciembre | Q34: =SUM(B34:P34) -> 0
A35: TOTAL année | B35: =SUM(B23:B34) -> 0 | C35: =SUM(C23:C34) -> 0 | D35: =SUM(D23:D34) -> 0 | E35: =SUM(E23:E34) -> 0 | F35: =SUM(F23:F34) -> 0 | G35: =SUM(G23:G34) -> 0 | H35: =SUM(H23:H34) -> 0 | I35: =SUM(I23:I34) -> 0 | ... Q35: =SUM(Q23:Q34) -> 0
A38: Année 2021 - Camino Portugués
A39: Mois \ Nationalité | B39: España | C39: Italia | D39: Alemania | E39: Estados Unidos | F39: Portugal | G39: Francia | H39: Reino Unido | I39: Irlanda | J39: Corea | K39: Brasil | L39: Australia | M39: Canadá | N39: Polonia | O39: Holanda | P39: México | Q39: Total
A40: Enero | Q40: =SUM(B40:P40) -> 0
A41: Febrero | Q41: =SUM(B41:P41) -> 0
A42: Marzo | Q42: =SUM(B42:P42) -> 0
A43: Abril | Q43: =SUM(B43:P43) -> 0
A44: Mayo | Q44: =SUM(B44:P44) -> 0
A45: Junio | Q45: =SUM(B45:P45) -> 0
...

Sheet C_4D_via_plata
A1: Table C - 4D : Vía de la Plata
A2: 1080 cellules : 6 ans × 12 mois × 15 nationalités. Matrice mois × nationalité par année.
A4: Année 2019 - Vía de la Plata
A5: Mois \ Nationalité | B5: España | C5: Italia | D5: Alemania | E5: Estados Unidos | F5: Portugal | G5: Francia | H5: Reino Unido | I5: Irlanda | J5: Corea | K5: Brasil | L5: Australia | M5: Canadá | N5: Polonia | O5: Holanda | P5: México | Q5: Total
A6: Enero | Q6: =SUM(B6:P6) -> 0
A7: Febrero | Q7: =SUM(B7:P7) -> 0
A8: Marzo | Q8: =SUM(B8:P8) -> 0
A9: Abril | Q9: =SUM(B9:P9) -> 0
A10: Mayo | Q10: =SUM(B10:P10) -> 0
A11: Junio | Q11: =SUM(B11:P11) -> 0
A12: Julio | Q12: =SUM(B12:P12) -> 0
A13: Agosto | Q13: =SUM(B13:P13) -> 0
A14: Septiembre | Q14: =SUM(B14:P14) -> 0
A15: Octubre | Q15: =SUM(B15:P15) -> 0
A16: Noviembre | Q16: =SUM(B16:P16) -> 0
A17: Diciembre | Q17: =SUM(B17:P17) -> 0
A18: TOTAL année | B18: =SUM(B6:B17) -> 0 | C18: =SUM(C6:C17) -> 0 | D18: =SUM(D6:D17) -> 0 | E18: =SUM(E6:E17) -> 0 | F18: =SUM(F6:F17) -> 0 | G18: =SUM(G6:G17) -> 0 | H18: =SUM(H6:H17) -> 0 | I18: =SUM(I6:I17) -> 0 | ... Q18: =SUM(Q6:Q17) -> 0
A21: Année 2020 - Vía de la Plata
A22: Mois \ Nationalité | B22: España | C22: Italia | D22: Alemania | E22: Estados Unidos | F22: Portugal | G22: Francia | H22: Reino Unido | I22: Irlanda | J22: Corea | K22: Brasil | L22: Australia | M22: Canadá | N22: Polonia | O22: Holanda | P22: México | Q22: Total
A23: Enero | Q23: =SUM(B23:P23) -> 0
A24: Febrero | Q24: =SUM(B24:P24) -> 0
A25: Marzo | Q25: =SUM(B25:P25) -> 0
A26: Abril | Q26: =SUM(B26:P26) -> 0
A27: Mayo | Q27: =SUM(B27:P27) -> 0
A28: Junio | Q28: =SUM(B28:P28) -> 0
A29: Julio | Q29: =SUM(B29:P29) -> 0
A30: Agosto | Q30: =SUM(B30:P30) -> 0
A31: Septiembre | Q31: =SUM(B31:P31) -> 0
A32: Octubre | Q32: =SUM(B32:P32) -> 0
A33: Noviembre | Q33: =SUM(B33:P33) -> 0
A34: Diciembre | Q34: =SUM(B34:P34) -> 0
A35: TOTAL année | B35: =SUM(B23:B34) -> 0 | C35: =SUM(C23:C34) -> 0 | D35: =SUM(D23:D34) -> 0 | E35: =SUM(E23:E34) -> 0 | F35: =SUM(F23:F34) -> 0 | G35: =SUM(G23:G34) -> 0 | H35: =SUM(H23:H34) -> 0 | I35: =SUM(I23:I34) -> 0 | ... Q35: =SUM(Q23:Q34) -> 0
A38: Année 2021 - Vía de la Plata
A39: Mois \ Nationalité | B39: España | C39: Italia | D39: Alemania | E39: Estados Unidos | F39: Portugal | G39: Francia | H39: Reino Unido | I39: Irlanda | J39: Corea | K39: Brasil | L39: Australia | M39: Canadá | N39: Polonia | O39: Holanda | P39: México | Q39: Total
A40: Enero | Q40: =SUM(B40:P40) -> 0
A41: Febrero | Q41: =SUM(B41:P41) -> 0
A42: Marzo | Q42: =SUM(B42:P42) -> 0
A43: Abril | Q43: =SUM(B43:P43) -> 0
A44: Mayo | Q44: =SUM(B44:P44) -> 0
A45: Junio | Q45: =SUM(B45:P45) -> 0
...

Sheet C_4D_del_norte
A1: Table C - 4D : Camino del Norte
A2: 1080 cellules : 6 ans × 12 mois × 15 nationalités. Matrice mois × nationalité par année.
A4: Année 2019 - Camino del Norte
A5: Mois \ Nationalité | B5: España | C5: Italia | D5: Alemania | E5: Estados Unidos | F5: Portugal | G5: Francia | H5: Reino Unido | I5: Irlanda | J5: Corea | K5: Brasil | L5: Australia | M5: Canadá | N5: Polonia | O5: Holanda | P5: México | Q5: Total
A6: Enero | Q6: =SUM(B6:P6) -> 0
A7: Febrero | Q7: =SUM(B7:P7) -> 0
A8: Marzo | Q8: =SUM(B8:P8) -> 0
A9: Abril | Q9: =SUM(B9:P9) -> 0
A10: Mayo | Q10: =SUM(B10:P10) -> 0
A11: Junio | Q11: =SUM(B11:P11) -> 0
A12: Julio | Q12: =SUM(B12:P12) -> 0
A13: Agosto | Q13: =SUM(B13:P13) -> 0
A14: Septiembre | Q14: =SUM(B14:P14) -> 0
A15: Octubre | Q15: =SUM(B15:P15) -> 0
A16: Noviembre | Q16: =SUM(B16:P16) -> 0
A17: Diciembre | Q17: =SUM(B17:P17) -> 0
A18: TOTAL année | B18: =SUM(B6:B17) -> 0 | C18: =SUM(C6:C17) -> 0 | D18: =SUM(D6:D17) -> 0 | E18: =SUM(E6:E17) -> 0 | F18: =SUM(F6:F17) -> 0 | G18: =SUM(G6:G17) -> 0 | H18: =SUM(H6:H17) -> 0 | I18: =SUM(I6:I17) -> 0 | ... Q18: =SUM(Q6:Q17) -> 0
A21: Année 2020 - Camino del Norte
A22: Mois \ Nationalité | B22: España | C22: Italia | D22: Alemania | E22: Estados Unidos | F22: Portugal | G22: Francia | H22: Reino Unido | I22: Irlanda | J22: Corea | K22: Brasil | L22: Australia | M22: Canadá | N22: Polonia | O22: Holanda | P22: México | Q22: Total
A23: Enero | Q23: =SUM(B23:P23) -> 0
A24: Febrero | Q24: =SUM(B24:P24) -> 0
A25: Marzo | Q25: =SUM(B25:P25) -> 0
A26: Abril | Q26: =SUM(B26:P26) -> 0
A27: Mayo | Q27: =SUM(B27:P27) -> 0
A28: Junio | Q28: =SUM(B28:P28) -> 0
A29: Julio | Q29: =SUM(B29:P29) -> 0
A30: Agosto | Q30: =SUM(B30:P30) -> 0
A31: Septiembre | Q31: =SUM(B31:P31) -> 0
A32: Octubre | Q32: =SUM(B32:P32) -> 0
A33: Noviembre | Q33: =SUM(B33:P33) -> 0
A34: Diciembre | Q34: =SUM(B34:P34) -> 0
A35: TOTAL année | B35: =SUM(B23:B34) -> 0 | C35: =SUM(C23:C34) -> 0 | D35: =SUM(D23:D34) -> 0 | E35: =SUM(E23:E34) -> 0 | F35: =SUM(F23:F34) -> 0 | G35: =SUM(G23:G34) -> 0 | H35: =SUM(H23:H34) -> 0 | I35: =SUM(I23:I34) -> 0 | ... Q35: =SUM(Q23:Q34) -> 0
A38: Année 2021 - Camino del Norte
A39: Mois \ Nationalité | B39: España | C39: Italia | D39: Alemania | E39: Estados Unidos | F39: Portugal | G39: Francia | H39: Reino Unido | I39: Irlanda | J39: Corea | K39: Brasil | L39: Australia | M39: Canadá | N39: Polonia | O39: Holanda | P39: México | Q39: Total
A40: Enero | Q40: =SUM(B40:P40) -> 0
A41: Febrero | Q41: =SUM(B41:P41) -> 0
A42: Marzo | Q42: =SUM(B42:P42) -> 0
A43: Abril | Q43: =SUM(B43:P43) -> 0
A44: Mayo | Q44: =SUM(B44:P44) -> 0
A45: Junio | Q45: =SUM(B45:P45) -> 0
...

Sheet 99_controle_qualite
A1: Contrôle qualité & calcul empirique du biais SJPP
A3: 1. Cohérence des totaux annuels (Table A vs AFCC)
A5: Année | B5: Total Table A | C5: Référence AFCC | D5: Écart absolu | E5: Écart % | F5: Statut
A6: 2019 | B6: =A_temps_x_camino!N14 -> 344289 | C6: 347578 | D6: =B6-C6 -> -3289 | E6: =IFERROR((B6-C6)/C6,"") -> -0.0094626242 | F6: =IF(ABS(E6)<0.01,"OK",IF(ABS(E6)<0.05,"Vérifier","ANOMALIE")) -> OK
A7: 2020 | B7: =A_temps_x_camino!N29 -> 54144 | C7: 54144 | D7: =B7-C7 -> 0 | E7: =IFERROR((B7-C7)/C7,"") -> 0 | F7: =IF(ABS(E7)<0.01,"OK",IF(ABS(E7)<0.05,"Vérifier","ANOMALIE")) -> OK
A8: 2021 | B8: =A_temps_x_camino!N44 -> -51666 | C8: 178912 | D8: =B8-C8 -> -230578 | E8: =IFERROR((B8-C8)/C8,"") -> -1.2887788 | F8: =IF(ABS(E8)<0.01,"OK",IF(ABS(E8)<0.05,"Vérifier","ANOMALIE")) -> ANOMALIE
A9: 2022 | B9: =A_temps_x_camino!N59 -> 0 | C9: 438307 | D9: =B9-C9 -> -438307 | E9: =IFERROR((B9-C9)/C9,"") -> -1 | F9: =IF(ABS(E9)<0.01,"OK",IF(ABS(E9)<0.05,"Vérifier","ANOMALIE")) -> ANOMALIE
A10: 2023 | B10: =A_temps_x_camino!N74 -> 0 | C10: 445397 | D10: =B10-C10 -> -445397 | E10: =IFERROR((B10-C10)/C10,"") -> -1 | F10: =IF(ABS(E10)<0.01,"OK",IF(ABS(E10)<0.05,"Vérifier","ANOMALIE")) -> ANOMALIE
A11: 2024 | B11: =A_temps_x_camino!N89 -> 100831 | C11: n.d.
A14: 2. Biais SJPP empirique (ratio Aragonés / (Aragonés + Francés))
A15: Principe : part des pèlerins de l'axe Voie d'Arles + Somport parmi l'ensemble 'français-compatible'
A17: Année | B17: Aragonés | C17: Francés | D17: Total A+F | E17: Biais SJPP | F17: Aragonés / Total annuel
A18: 2019 | B18: =A_temps_x_camino!N13 -> 0 | C18: =A_temps_x_camino!N6 -> 189928 | D18: =B18+C18 -> 189928 | E18: =IFERROR(B18/D18,"") -> 0 | F18: =IFERROR(B18/A_temps_x_camino!N14,"") -> 0
A19: 2020 | B19: =A_temps_x_camino!N28 -> 40227 | C19: =A_temps_x_camino!N21 -> 10252 | D19: =B19+C19 -> 50479 | E19: =IFERROR(B19/D19,"") -> 0.79690564 | F19: =IFERROR(B19/A_temps_x_camino!N29,"") -> 0.74296321
A20: 2021 | B20: =A_temps_x_camino!N43 -> 178912 | C20: =A_temps_x_camino!N36 -> 9594 | D20: =B20+C20 -> 188506 | E20: =IFERROR(B20/D20,"") -> 0.94910507 | F20: =IFERROR(B20/A_temps_x_camino!N44,"") -> -3.4628576
A21: 2022 | B21: =A_temps_x_camino!N58 -> -11285 | C21: =A_temps_x_camino!N51 -> 21335 | D21: =B21+C21 -> 10050 | E21: =IFERROR(B21/D21,"") -> -1.1228856 | F21: =IFERROR(B21/A_temps_x_camino!N59,"")
A22: 2023 | B22: =A_temps_x_camino!N73 -> 0 | C22: =A_temps_x_camino!N66 -> 24104 | D22: =B22+C22 -> 24104 | E22: =IFERROR(B22/D22,"") -> 0 | F22: =IFERROR(B22/A_temps_x_camino!N74,"")
A23: 2024 | B23: =A_temps_x_camino!N88 -> 242037 | C23: =A_temps_x_camino!N81 -> 74753 | D23: =B23+C23 -> 316790 | E23: =IFERROR(B23/D23,"") -> 0.7640298 | F23: =IFERROR(B23/A_temps_x_camino!N89,"") -> 2.4004225
A25: MOYENNE 2019-2024 | E25: =IFERROR(AVERAGE(E18:E23),"") -> 0.23119249 | F25: =IFERROR(AVERAGE(F18:F23),"") -> -0.079867972
A27: Rappel estimation initiale : 12% (non sourcée). À remplacer par la moyenne ci-dessus.
A30: 3. Part des pèlerins français sur le Camino Aragonés
A31: Depuis Table C_4D_aragones - Nationalité France (colonne G) vs Total annuel.
A33: Année | B33: Français Aragonés | C33: Total Aragonés | D33: Part Français (%)
A34: 2019 | B34: =C_4D_aragones!G18 -> 0 | C34: =C_4D_aragones!Q18 -> 0 | D34: =IFERROR(B34/C34,"")
A35: 2020 | B35: =C_4D_aragones!G35 -> 0 | C35: =C_4D_aragones!Q35 -> 0 | D35: =IFERROR(B35/C35,"")
A36: 2021 | B36: =C_4D_aragones!G52 -> 0 | C36: =C_4D_aragones!Q52 -> 0 | D36: =IFERROR(B36/C36,"")
A37: 2022 | B37: =C_4D_aragones!G69 -> 0 | C37: =C_4D_aragones!Q69 -> 0 | D37: =IFERROR(B37/C37,"")
A38: 2023 | B38: =C_4D_aragones!G86 -> 0 | C38: =C_4D_aragones!Q86 -> 0 | D38: =IFERROR(B38/C38,"")
A39: 2024 | B39: =C_4D_aragones!G103 -> 0 | C39: =C_4D_aragones!Q103 -> 0 | D39: =IFERROR(B39/C39,"")
